[2025-05-12T22:22:44.506+0100] {local_task_job_runner.py:120} INFO - ::group::Pre task execution logs
[2025-05-12T22:22:44.520+0100] {taskinstance.py:2076} INFO - Dependencies all met for dep_context=non-requeueable deps ti=<TaskInstance: youtube_daily_pipeline.dbt_run manual__2025-05-12T21:22:39.790133+00:00 [queued]>
[2025-05-12T22:22:44.523+0100] {taskinstance.py:2076} INFO - Dependencies all met for dep_context=requeueable deps ti=<TaskInstance: youtube_daily_pipeline.dbt_run manual__2025-05-12T21:22:39.790133+00:00 [queued]>
[2025-05-12T22:22:44.523+0100] {taskinstance.py:2306} INFO - Starting attempt 1 of 2
[2025-05-12T22:22:44.527+0100] {taskinstance.py:2330} INFO - Executing <Task(BashOperator): dbt_run> on 2025-05-12 21:22:39.790133+00:00
[2025-05-12T22:22:44.533+0100] {logging_mixin.py:188} WARNING - /Users/moeinfahmide/miniconda3/envs/open-air/lib/python3.12/site-packages/airflow/task/task_runner/standard_task_runner.py:62 DeprecationWarning: This process (pid=6258) is multi-threaded, use of fork() may lead to deadlocks in the child.
[2025-05-12T22:22:44.533+0100] {standard_task_runner.py:64} INFO - Started process 6260 to run task
[2025-05-12T22:22:44.532+0100] {standard_task_runner.py:90} INFO - Running: ['airflow', 'tasks', 'run', 'youtube_daily_pipeline', 'dbt_run', 'manual__2025-05-12T21:22:39.790133+00:00', '--job-id', '31', '--raw', '--subdir', 'DAGS_FOLDER/youtube_pipeline.py', '--cfg-path', '/var/folders/x8/bvc5rcpd5t12mfz1khbckdsm0000gn/T/tmp20kwdt42']
[2025-05-12T22:22:44.534+0100] {standard_task_runner.py:91} INFO - Job 31: Subtask dbt_run
[2025-05-12T22:22:44.552+0100] {task_command.py:426} INFO - Running <TaskInstance: youtube_daily_pipeline.dbt_run manual__2025-05-12T21:22:39.790133+00:00 [running]> on host macbookair.lan
[2025-05-12T22:22:44.680+0100] {taskinstance.py:2648} INFO - Exporting env vars: AIRFLOW_CTX_DAG_OWNER='you' AIRFLOW_CTX_DAG_ID='youtube_daily_pipeline' AIRFLOW_CTX_TASK_ID='dbt_run' AIRFLOW_CTX_EXECUTION_DATE='2025-05-12T21:22:39.790133+00:00' AIRFLOW_CTX_TRY_NUMBER='1' AIRFLOW_CTX_DAG_RUN_ID='manual__2025-05-12T21:22:39.790133+00:00'
[2025-05-12T22:22:44.681+0100] {taskinstance.py:430} INFO - ::endgroup::
[2025-05-12T22:22:44.688+0100] {subprocess.py:63} INFO - Tmp dir root location: /var/folders/x8/bvc5rcpd5t12mfz1khbckdsm0000gn/T
[2025-05-12T22:22:44.688+0100] {subprocess.py:75} INFO - Running command: ['/bin/bash', '-c', 'cd "/Users/moeinfahmide/Desktop/Job/Learning/Data Engineering/projects/youtube/youtube_dbt" && dbt run --project-dir "/Users/moeinfahmide/Desktop/Job/Learning/Data Engineering/projects/youtube/youtube_dbt" --profiles-dir "/Users/moeinfahmide/Desktop/Job/Learning/Data Engineering/projects/youtube" --models staging+ marts+']
[2025-05-12T22:22:44.692+0100] {subprocess.py:86} INFO - Output:
[2025-05-12T22:22:45.859+0100] {subprocess.py:93} INFO - [0m21:22:45  Running with dbt=1.9.4
[2025-05-12T22:22:45.862+0100] {subprocess.py:93} INFO - [0m21:22:45  Encountered an error:
[2025-05-12T22:22:45.863+0100] {subprocess.py:93} INFO - Runtime Error
[2025-05-12T22:22:45.863+0100] {subprocess.py:93} INFO - 
[2025-05-12T22:22:45.863+0100] {subprocess.py:93} INFO -   dbt encountered an error while trying to read your profiles.yml file.
[2025-05-12T22:22:45.864+0100] {subprocess.py:93} INFO - 
[2025-05-12T22:22:45.864+0100] {subprocess.py:93} INFO -   Runtime Error
[2025-05-12T22:22:45.864+0100] {subprocess.py:93} INFO -     Syntax error near line 10
[2025-05-12T22:22:45.865+0100] {subprocess.py:93} INFO -     ------------------------------
[2025-05-12T22:22:45.865+0100] {subprocess.py:93} INFO -     7  |       host:     "{{ env_var('DB_HOST') }}"
[2025-05-12T22:22:45.865+0100] {subprocess.py:93} INFO -     8  |       user:     "{{ env_var('DB_USER') }}"
[2025-05-12T22:22:45.865+0100] {subprocess.py:93} INFO -     9  |       pass:     "{{ env_var('DB_PASSWORD') }}"
[2025-05-12T22:22:45.865+0100] {subprocess.py:93} INFO -     10 |       port:     {{ env_var('DB_PORT') }}
[2025-05-12T22:22:45.866+0100] {subprocess.py:93} INFO -     11 |       dbname:   "{{ env_var('DB_NAME') }}"
[2025-05-12T22:22:45.866+0100] {subprocess.py:93} INFO -     12 |       schema:   analytics
[2025-05-12T22:22:45.866+0100] {subprocess.py:93} INFO -     13 |       threads:  1
[2025-05-12T22:22:45.866+0100] {subprocess.py:93} INFO - 
[2025-05-12T22:22:45.866+0100] {subprocess.py:93} INFO -     Raw Error:
[2025-05-12T22:22:45.867+0100] {subprocess.py:93} INFO -     ------------------------------
[2025-05-12T22:22:45.867+0100] {subprocess.py:93} INFO -     while constructing a mapping
[2025-05-12T22:22:45.867+0100] {subprocess.py:93} INFO -       in "<unicode string>", line 10, column 17
[2025-05-12T22:22:45.867+0100] {subprocess.py:93} INFO -     found unhashable key
[2025-05-12T22:22:45.868+0100] {subprocess.py:93} INFO -       in "<unicode string>", line 10, column 18
[2025-05-12T22:22:45.868+0100] {subprocess.py:93} INFO - 
[2025-05-12T22:22:46.820+0100] {subprocess.py:97} INFO - Command exited with return code 2
[2025-05-12T22:22:46.821+0100] {taskinstance.py:441} INFO - ::group::Post task execution logs
[2025-05-12T22:22:46.824+0100] {taskinstance.py:2905} ERROR - Task failed with exception
Traceback (most recent call last):
  File "/Users/moeinfahmide/miniconda3/envs/open-air/lib/python3.12/site-packages/airflow/models/taskinstance.py", line 465, in _execute_task
    result = _execute_callable(context=context, **execute_callable_kwargs)
             ^^^^^^^^^^^^^^^^^^^^^^^^^^^^^^^^^^^^^^^^^^^^^^^^^^^^^^^^^^^^^
  File "/Users/moeinfahmide/miniconda3/envs/open-air/lib/python3.12/site-packages/airflow/models/taskinstance.py", line 432, in _execute_callable
    return execute_callable(context=context, **execute_callable_kwargs)
           ^^^^^^^^^^^^^^^^^^^^^^^^^^^^^^^^^^^^^^^^^^^^^^^^^^^^^^^^^^^^
  File "/Users/moeinfahmide/miniconda3/envs/open-air/lib/python3.12/site-packages/airflow/models/baseoperator.py", line 401, in wrapper
    return func(self, *args, **kwargs)
           ^^^^^^^^^^^^^^^^^^^^^^^^^^^
  File "/Users/moeinfahmide/miniconda3/envs/open-air/lib/python3.12/site-packages/airflow/operators/bash.py", line 243, in execute
    raise AirflowException(
airflow.exceptions.AirflowException: Bash command failed. The command returned a non-zero exit code 2.
[2025-05-12T22:22:46.828+0100] {taskinstance.py:1206} INFO - Marking task as UP_FOR_RETRY. dag_id=youtube_daily_pipeline, task_id=dbt_run, run_id=manual__2025-05-12T21:22:39.790133+00:00, execution_date=20250512T212239, start_date=20250512T212244, end_date=20250512T212246
[2025-05-12T22:22:46.832+0100] {standard_task_runner.py:110} ERROR - Failed to execute job 31 for task dbt_run (Bash command failed. The command returned a non-zero exit code 2.; 6260)
[2025-05-12T22:22:46.840+0100] {local_task_job_runner.py:243} INFO - Task exited with return code 1
[2025-05-12T22:22:46.848+0100] {taskinstance.py:3503} INFO - 0 downstream tasks scheduled from follow-on schedule check
[2025-05-12T22:22:46.848+0100] {local_task_job_runner.py:222} INFO - ::endgroup::
